Workbook

Sheet Main
A1: C3S Operational TIER 1 Indicators based on ERA5
A2: DECADAL
A4: Number of windstorms (vorticity)
A6: Region | B6: 1979-1988 | C6: 1989-1998 | D6: 1999-2008 | E6: 2009-2021 | F6: 1979-2021
A7: Europe (XWS Domain) | B7: 1106 | C7: 1100 | D7: 1070 | E7: 1385 | F7: 4661
A8: UK | B8: 311 | C8: 286 | D8: 293 | E8: 370 | F8: 1260
A9: France | B9: 230 | C9: 203 | D9: 211 | E9: 272 | F9: 916
A10: Germany | B10: 140 | C10: 131 | D10: 140 | E10: 168 | F10: 579
A11: BeNeLux | B11: 88 | C11: 60 | D11: 69 | E11: 85 | F11: 302
A12: BeNeLuxMark | B12: 186 | C12: 151 | D12: 151 | E12: 195 | F12: 683
A13: Scandinavia | B13: 546 | C13: 593 | D13: 527 | E13: 678 | F13: 2344
A14: Iberian Peninsula | B14: 167 | C14: 165 | D14: 171 | E14: 245 | F14: 748
A16: Number of windstorms (u10m land only)
A18: Region | B18: 1979-1988 | C18: 1989-1998 | D18: 1999-2008 | E18: 2009-2021 | F18: 1979-2021
A19: Europe (XWS Domain) | B19: 588 | C19: 593 | D19: 549 | E19: 649 | F19: 2379
A20: UK | B20: 69 | C20: 50 | D20: 66 | E20: 71 | F20: 256
A21: France | B21: 88 | C21: 81 | D21: 71 | E21: 98 | F21: 338
A22: Germany | B22: 44 | C22: 51 | D22: 46 | E22: 48 | F22: 189
A23: BeNeLux | B23: 41 | C23: 41 | D23: 29 | E23: 28 | F23: 139
A24: BeNeLuxMark | B24: 69 | C24: 82 | D24: 61 | E24: 67 | F24: 279
A25: Scandinavia | B25: 326 | C25: 333 | D25: 297 | E25: 350 | F25: 1306
A26: Iberian Peninsula | B26: 54 | C26: 57 | D26: 61 | E26: 78 | F26: 250
A28: Number of extreme windstorms | H28: Number of extreme windstorms | O28: Number of extreme windstorms
A29: (u10m land only) (> 15.6 m/s) | H29: (u10m land only) (> 20.0 m/s) | O29: (u10m land only) (> 25.0 m/s)
A31: Region | B31: 1979-1988 | C31: 1989-1998 | D31: 1999-2008 | E31: 2009-2021 | F31: 1979-2021 | H31: Region | I31: 1979-1988 | J31: 1989-1998 | K31: 1999-2008 | L31: 2009-2021 | M31: 1979-2021 | O31: Region | P31: 1979-1988 | Q31: 1989-1998 | R31: 1999-2008 | S31: 2009-2021 | T31: 1979-2021
A32: Europe (XWS Domain) | B32: 333 | C32: 315 | D32: 297 | E32: 347 | F32: 1292 | H32: Europe (XWS Domain) | I32: 122 | J32: 101 | K32: 95 | L32: 120 | M32: 438 | O32: Europe (XWS Domain) | P32: 10 | Q32: 15 | R32: 10 | S32: 12 | T32: 47
A33: UK | B33: 54 | C33: 39 | D33: 52 | E33: 62 | F33: 207 | H33: UK | I33: 21 | J33: 12 | K33: 22 | L33: 26 | M33: 81 | O33: UK | P33: 5 | Q33: 2 | R33: 2 | S33: 3 | T33: 12
A34: France | B34: 62 | C34: 46 | D34: 42 | E34: 60 | F34: 210 | H34: France | I34: 20 | J34: 11 | K34: 11 | L34: 14 | M34: 56 | O34: France | P34: 0 | Q34: 0 | R34: 3 | S34: 0 | T34: 3
A35: Germany | B35: 24 | C35: 31 | D35: 28 | E35: 30 | F35: 113 | H35: Germany | I35: 7 | J35: 8 | K35: 5 | L35: 7 | M35: 27 | O35: Germany | P35: 0 | Q35: 2 | R35: 1 | S35: 0 | T35: 3
A36: BeNeLux | B36: 30 | C36: 33 | D36: 19 | E36: 23 | F36: 105 | H36: BeNeLux | I36: 14 | J36: 10 | K36: 7 | L36: 7 | M36: 38 | O36: BeNeLux | P36: 0 | Q36: 3 | R36: 0 | S36: 0 | T36: 3
A37: BeNeLuxMark | B37: 48 | C37: 65 | D37: 40 | E37: 45 | F37: 198 | H37: BeNeLuxMark | I37: 22 | J37: 21 | K37: 16 | L37: 12 | M37: 71 | O37: BeNeLuxMark | P37: 0 | Q37: 4 | R37: 2 | S37: 1 | T37: 7
A38: Scandinavia | B38: 161 | C38: 149 | D38: 142 | E38: 153 | F38: 605 | H38: Scandinavia | I38: 62 | J38: 53 | K38: 47 | L38: 66 | M38: 228 | O38: Scandinavia | P38: 7 | Q38: 11 | R38: 5 | S38: 11 | T38: 34
A39: Iberian Peninsula | B39: 26 | C39: 29 | D39: 29 | E39: 39 | F39: 123 | H39: Iberian Peninsula | I39: 7 | J39: 5 | K39: 7 | L39: 8 | M39: 27 | O39: Iberian Peninsula | P39: 0 | Q39: 0 | R39: 0 | S39: 0 | T39: 0
A42: Mean maximum wind speed (u10m land only) | H42: Mean maximum wind speed (u10m land only) | O42: Mean maximum wind speed (u10m land only)
A43: (> 15.6 m/s) | H43: (> 20.0 m/s) | O43: (> 25.0 m/s)
A45: Region | B45: 1979-1988 | C45: 1989-1998 | D45: 1999-2008 | E45: 2009-2021 | F45: 1979-2021 | H45: Region | I45: 1979-1988 | J45: 1989-1998 | K45: 1999-2008 | L45: 2009-2021 | M45: 1979-2021 | O45: Region | P45: 1979-1988 | Q45: 1989-1998 | R45: 1999-2008 | S45: 2009-2021 | T45: 1979-2021
A46: Europe (XWS Domain) | B46: 19.288 | C46: 19.345 | D46: 19.139 | E46: 19.267 | F46: 19.26 | H46: Europe (XWS Domain) | I46: 22.257 | J46: 22.46 | K46: 22.295 | L46: 22.232 | M46: 22.307 | O46: Europe (XWS Domain) | P46: 26.941 | Q46: 26.707 | R46: 26.47 | S46: 26.6 | T46: 26.69
A47: UK | B47: 19.913 | C47: 18.923 | D47: 19.915 | E47: 20.001 | F47: 19.703 | H47: UK | I47: 23.234 | J47: 21.92 | K47: 22.401 | L47: 22.402 | M47: 22.503 | O47: UK | P47: 26.73 | Q47: 25.56 | R47: 26.6 | S47: 26.77 | T47: 26.504
A48: France | B48: 18.921 | C48: 18.992 | D48: 18.738 | E48: 18.82 | F48: 18.865 | H48: France | I48: 21.622 | J48: 22.121 | K48: 22.48 | L48: 21.632 | M48: 21.937 | O48: France | P48: 0 | Q48: 0 | R48: 26.175 | S48: 0 | T48: 26.175
A49: Germany | B49: 19.73 | C49: 19.02 | D49: 18.408 | E49: 18.693 | F49: 18.936 | H49: Germany | I49: 22.045 | J49: 22.717 | K49: 22.387 | L49: 22.274 | M49: 22.335 | O49: Germany | P49: 0 | Q49: 25.765 | R49: 25.97 | S49: 0 | T49: 25.833
...

Sheet Graphs - Total No Storms
A1: C3S Operational TIER 1 Indicators based on ERA5
A2: DECADAL
A5: Number of windstorms (vorticity)
A7: Region | B7: 1979-1988 | C7: 1989-1998 | D7: 1999-2008 | E7: 2009-2021 | F7: 1979-2021
A8: Europe (XWS Domain) | B8: =Main!B7 -> 1106 | C8: =Main!C7 -> 1100 | D8: =Main!D7 -> 1070 | E8: =Main!E7 -> 1385 | F8: =Main!F7 -> 4661
A9: UK | B9: =Main!B8 -> 311 | C9: =Main!C8 -> 286 | D9: =Main!D8 -> 293 | E9: =Main!E8 -> 370 | F9: =Main!F8 -> 1260
A10: France | B10: =Main!B9 -> 230 | C10: =Main!C9 -> 203 | D10: =Main!D9 -> 211 | E10: =Main!E9 -> 272 | F10: =Main!F9 -> 916
A11: Germany | B11: =Main!B10 -> 140 | C11: =Main!C10 -> 131 | D11: =Main!D10 -> 140 | E11: =Main!E10 -> 168 | F11: =Main!F10 -> 579
A12: BeNeLux | B12: =Main!B11 -> 88 | C12: =Main!C11 -> 60 | D12: =Main!D11 -> 69 | E12: =Main!E11 -> 85 | F12: =Main!F11 -> 302
A13: BeNeLuxMark | B13: =Main!B12 -> 186 | C13: =Main!C12 -> 151 | D13: =Main!D12 -> 151 | E13: =Main!E12 -> 195 | F13: =Main!F12 -> 683
A14: Scandinavia | B14: =Main!B13 -> 546 | C14: =Main!C13 -> 593 | D14: =Main!D13 -> 527 | E14: =Main!E13 -> 678 | F14: =Main!F13 -> 2344
A15: Iberian Peninsula | B15: =Main!B14 -> 167 | C15: =Main!C14 -> 165 | D15: =Main!D14 -> 171 | E15: =Main!E14 -> 245 | F15: =Main!F14 -> 748
A17: Number of windstorms (u10m land only)
A19: Region | B19: 1979-1988 | C19: 1989-1998 | D19: 1999-2008 | E19: 2009-2021 | F19: 1979-2021
A20: Europe (XWS Domain) | B20: =Main!B19 -> 588 | C20: =Main!C19 -> 593 | D20: =Main!D19 -> 549 | E20: =Main!E19 -> 649 | F20: =Main!F19 -> 2379
A21: UK | B21: =Main!B20 -> 69 | C21: =Main!C20 -> 50 | D21: =Main!D20 -> 66 | E21: =Main!E20 -> 71 | F21: =Main!F20 -> 256
A22: France | B22: =Main!B21 -> 88 | C22: =Main!C21 -> 81 | D22: =Main!D21 -> 71 | E22: =Main!E21 -> 98 | F22: =Main!F21 -> 338
A23: Germany | B23: =Main!B22 -> 44 | C23: =Main!C22 -> 51 | D23: =Main!D22 -> 46 | E23: =Main!E22 -> 48 | F23: =Main!F22 -> 189
A24: BeNeLux | B24: =Main!B23 -> 41 | C24: =Main!C23 -> 41 | D24: =Main!D23 -> 29 | E24: =Main!E23 -> 28 | F24: =Main!F23 -> 139
A25: BeNeLuxMark | B25: =Main!B24 -> 69 | C25: =Main!C24 -> 82 | D25: =Main!D24 -> 61 | E25: =Main!E24 -> 67 | F25: =Main!F24 -> 279
A26: Scandinavia | B26: =Main!B25 -> 326 | C26: =Main!C25 -> 333 | D26: =Main!D25 -> 297 | E26: =Main!E25 -> 350 | F26: =Main!F25 -> 1306
A27: Iberian Peninsula | B27: =Main!B26 -> 54 | C27: =Main!C26 -> 57 | D27: =Main!D26 -> 61 | E27: =Main!E26 -> 78 | F27: =Main!F26 -> 250
M86: `

Sheet Graphs - Total No Extr. Storms
A1: C3S Operational TIER 1 Indicators based on ERA5
A2: DECADAL
A5: Number of extreme windstorms | H5: Number of extreme windstorms | O5: Number of extreme windstorms
A6: (u10m land only) (> 15.6 m/s) | H6: (u10m land only) (> 20.0 m/s) | O6: (u10m land only) (> 25.0 m/s)
A8: =Main!A31 -> Region | B8: =Main!B31 -> 1979-1988 | C8: =Main!C31 -> 1989-1998 | D8: =Main!D31 -> 1999-2008 | E8: =Main!E31 -> 2009-2021 | F8: =Main!F31 -> 1979-2021 | H8: =Main!H31 -> Region | I8: =Main!I31 -> 1979-1988 | J8: =Main!J31 -> 1989-1998 | K8: =Main!K31 -> 1999-2008 | L8: =Main!L31 -> 2009-2021 | M8: =Main!M31 -> 1979-2021 | O8: =Main!O31 -> Region | P8: =Main!P31 -> 1979-1988 | Q8: =Main!Q31 -> 1989-1998 | R8: =Main!R31 -> 1999-2008 | S8: =Main!S31 -> 2009-2021 | T8: =Main!T31 -> 1979-2021
A9: =Main!A32 -> Europe (XWS Domain) | B9: =Main!B32 -> 333 | C9: =Main!C32 -> 315 | D9: =Main!D32 -> 297 | E9: =Main!E32 -> 347 | F9: =Main!F32 -> 1292 | H9: =Main!H32 -> Europe (XWS Domain) | I9: =Main!I32 -> 122 | J9: =Main!J32 -> 101 | K9: =Main!K32 -> 95 | L9: =Main!L32 -> 120 | M9: =Main!M32 -> 438 | O9: =Main!O32 -> Europe (XWS Domain) | P9: =Main!P32 -> 10 | Q9: =Main!Q32 -> 15 | R9: =Main!R32 -> 10 | S9: =Main!S32 -> 12 | T9: =Main!T32 -> 47
A10: =Main!A33 -> UK | B10: =Main!B33 -> 54 | C10: =Main!C33 -> 39 | D10: =Main!D33 -> 52 | E10: =Main!E33 -> 62 | F10: =Main!F33 -> 207 | H10: =Main!H33 -> UK | I10: =Main!I33 -> 21 | J10: =Main!J33 -> 12 | K10: =Main!K33 -> 22 | L10: =Main!L33 -> 26 | M10: =Main!M33 -> 81 | O10: =Main!O33 -> UK | P10: =Main!P33 -> 5 | Q10: =Main!Q33 -> 2 | R10: =Main!R33 -> 2 | S10: =Main!S33 -> 3 | T10: =Main!T33 -> 12
A11: =Main!A34 -> France | B11: =Main!B34 -> 62 | C11: =Main!C34 -> 46 | D11: =Main!D34 -> 42 | E11: =Main!E34 -> 60 | F11: =Main!F34 -> 210 | H11: =Main!H34 -> France | I11: =Main!I34 -> 20 | J11: =Main!J34 -> 11 | K11: =Main!K34 -> 11 | L11: =Main!L34 -> 14 | M11: =Main!M34 -> 56 | O11: =Main!O34 -> France | P11: =Main!P34 -> 0 | Q11: =Main!Q34 -> 0 | R11: =Main!R34 -> 3 | S11: =Main!S34 -> 0 | T11: =Main!T34 -> 3
A12: =Main!A35 -> Germany | B12: =Main!B35 -> 24 | C12: =Main!C35 -> 31 | D12: =Main!D35 -> 28 | E12: =Main!E35 -> 30 | F12: =Main!F35 -> 113 | H12: =Main!H35 -> Germany | I12: =Main!I35 -> 7 | J12: =Main!J35 -> 8 | K12: =Main!K35 -> 5 | L12: =Main!L35 -> 7 | M12: =Main!M35 -> 27 | O12: =Main!O35 -> Germany | P12: =Main!P35 -> 0 | Q12: =Main!Q35 -> 2 | R12: =Main!R35 -> 1 | S12: =Main!S35 -> 0 | T12: =Main!T35 -> 3
A13: =Main!A36 -> BeNeLux | B13: =Main!B36 -> 30 | C13: =Main!C36 -> 33 | D13: =Main!D36 -> 19 | E13: =Main!E36 -> 23 | F13: =Main!F36 -> 105 | H13: =Main!H36 -> BeNeLux | I13: =Main!I36 -> 14 | J13: =Main!J36 -> 10 | K13: =Main!K36 -> 7 | L13: =Main!L36 -> 7 | M13: =Main!M36 -> 38 | O13: =Main!O36 -> BeNeLux | P13: =Main!P36 -> 0 | Q13: =Main!Q36 -> 3 | R13: =Main!R36 -> 0 | S13: =Main!S36 -> 0 | T13: =Main!T36 -> 3
A14: =Main!A37 -> BeNeLuxMark | B14: =Main!B37 -> 48 | C14: =Main!C37 -> 65 | D14: =Main!D37 -> 40 | E14: =Main!E37 -> 45 | F14: =Main!F37 -> 198 | H14: =Main!H37 -> BeNeLuxMark | I14: =Main!I37 -> 22 | J14: =Main!J37 -> 21 | K14: =Main!K37 -> 16 | L14: =Main!L37 -> 12 | M14: =Main!M37 -> 71 | O14: =Main!O37 -> BeNeLuxMark | P14: =Main!P37 -> 0 | Q14: =Main!Q37 -> 4 | R14: =Main!R37 -> 2 | S14: =Main!S37 -> 1 | T14: =Main!T37 -> 7
A15: =Main!A38 -> Scandinavia | B15: =Main!B38 -> 161 | C15: =Main!C38 -> 149 | D15: =Main!D38 -> 142 | E15: =Main!E38 -> 153 | F15: =Main!F38 -> 605 | H15: =Main!H38 -> Scandinavia | I15: =Main!I38 -> 62 | J15: =Main!J38 -> 53 | K15: =Main!K38 -> 47 | L15: =Main!L38 -> 66 | M15: =Main!M38 -> 228 | O15: =Main!O38 -> Scandinavia | P15: =Main!P38 -> 7 | Q15: =Main!Q38 -> 11 | R15: =Main!R38 -> 5 | S15: =Main!S38 -> 11 | T15: =Main!T38 -> 34
A16: =Main!A39 -> Iberian Peninsula | B16: =Main!B39 -> 26 | C16: =Main!C39 -> 29 | D16: =Main!D39 -> 29 | E16: =Main!E39 -> 39 | F16: =Main!F39 -> 123 | H16: =Main!H39 -> Iberian Peninsula | I16: =Main!I39 -> 7 | J16: =Main!J39 -> 5 | K16: =Main!K39 -> 7 | L16: =Main!L39 -> 8 | M16: =Main!M39 -> 27 | O16: =Main!O39 -> Iberian Peninsula | P16: =Main!P39 -> 0 | Q16: =Main!Q39 -> 0 | R16: =Main!R39 -> 0 | S16: =Main!S39 -> 0 | T16: =Main!T39 -> 0
M36: `

Sheet Graphs - Average SSI
A1: C3S Operational TIER 1 Indicators based on ERA5
A2: DECADAL
A5: Mean severity of extreme windstorms (SSI - values x10^7) | H5: Mean severity of extreme windstorms (SSI - values x10^7) | O5: Mean severity of extreme windstorms (SSI - values x10^7)
A6: (> 15.6 m/s) | H6: (> 20.0 m/s) | O6: (> 25.0 m/s)
A8: Region | B8: 1979-1988 | C8: 1989-1998 | D8: 1999-2008 | E8: 2009-2018 | F8: 1979-2018 | H8: Region | I8: 1979-1988 | J8: 1989-1998 | K8: 1999-2008 | L8: 2009-2018 | M8: 1979-2018 | O8: Region | P8: 1979-1988 | Q8: 1989-1998 | R8: 1999-2008 | S8: 2009-2018 | T8: 1979-2018
A9: Europe (XWS Domain) | B9: =Main!B60 -> 5.99 | C9: =Main!C60 -> 7.71 | D9: =Main!D60 -> 7.12 | E9: =Main!E60 -> 5.56 | F9: =Main!F60 -> 6.55 | H9: Europe (XWS Domain) | I9: =Main!I60 -> 2.78 | J9: =Main!J60 -> 3.7 | K9: =Main!K60 -> 3.39 | L9: =Main!L60 -> 2.17 | M9: =Main!M60 -> 2.97 | O9: Europe (XWS Domain) | P9: =Main!P60 -> 1.07 | Q9: =Main!Q60 -> 3.03 | R9: =Main!R60 -> 2.59 | S9: =Main!S60 -> 5.92 | T9: =Main!T60 -> 2.14
A10: UK | B10: =Main!B61 -> 5.15 | C10: =Main!C61 -> 3.53 | D10: =Main!D61 -> 5.53 | E10: =Main!E61 -> 4.88 | F10: =Main!F61 -> 4.77 | H10: UK | I10: =Main!I61 -> 2.6 | J10: =Main!J61 -> 2.96 | K10: =Main!K61 -> 2.87 | L10: =Main!L61 -> 2.36 | M10: =Main!M61 -> 2.68 | O10: UK | P10: =Main!P61 -> 0.98 | Q10: =Main!Q61 -> 0 | R10: =Main!R61 -> 2.37 | S10: =Main!S61 -> 0 | T10: =Main!T61 -> 1.9
A11: France | B11: =Main!B62 -> 0.829 | C11: =Main!C62 -> 2.17 | D11: =Main!D62 -> 4.47 | E11: =Main!E62 -> 2.12 | F11: =Main!F62 -> 2.34 | H11: France | I11: =Main!I62 -> 0.535 | J11: =Main!J62 -> 1.63 | K11: =Main!K62 -> 3.31 | L11: =Main!L62 -> 0.802 | M11: =Main!M62 -> 1.48 | O11: France | P11: =Main!P62 -> 0 | Q11: =Main!Q62 -> 0 | R11: =Main!R62 -> 0 | S11: =Main!S62 -> 0 | T11: =Main!T62 -> 0
A12: Germany | B12: =Main!B63 -> 0 | C12: =Main!C63 -> 1.41 | D12: =Main!D63 -> 0.588 | E12: =Main!E63 -> 0.666 | F12: =Main!F63 -> 0.87 | H12: Germany | I12: =Main!I63 -> 0 | J12: =Main!J63 -> 0 | K12: =Main!K63 -> 0 | L12: =Main!L63 -> 0 | M12: =Main!M63 -> 0 | O12: Germany | P12: =Main!P63 -> 0 | Q12: =Main!Q63 -> 0 | R12: =Main!R63 -> 0 | S12: =Main!S63 -> 0 | T12: =Main!T63 -> 0
A13: =Main!A64 -> BeNeLux | B13: =Main!B64 -> 1.61 | C13: =Main!C64 -> 2.75 | D13: =Main!D64 -> 0.745 | E13: =Main!E64 -> 0.699 | F13: =Main!F64 -> 1.58 | H13: =Main!H64 -> BeNeLux | I13: =Main!I64 -> 1.1 | J13: =Main!J64 -> 3.28 | K13: =Main!K64 -> 0 | L13: =Main!L64 -> 0 | M13: =Main!M64 -> 2.19 | O13: =Main!O64 -> BeNeLux | P13: =Main!P64 -> 0 | Q13: =Main!Q64 -> 0.949 | R13: =Main!R64 -> 0 | S13: =Main!S64 -> 0 | T13: =Main!T64 -> 0.949
A14: BeNeLux + Denmark | B14: =Main!B65 -> 3.61 | C14: =Main!C65 -> 2.9 | D14: =Main!D65 -> 3.97 | E14: =Main!E65 -> 2.16 | F14: =Main!F65 -> 3.14 | H14: BeNeLux + Denmark | I14: =Main!I65 -> 2.15 | J14: =Main!J65 -> 2.42 | K14: =Main!K65 -> 6.27 | L14: =Main!L65 -> 3.52 | M14: =Main!M65 -> 3.32 | O14: BeNeLux + Denmark | P14: =Main!P65 -> 0 | Q14: =Main!Q65 -> 0.949 | R14: =Main!R65 -> 2.12 | S14: =Main!S65 -> 0 | T14: =Main!T65 -> 1.53
A15: Scandinavia | B15: =Main!B66 -> 1.94 | C15: =Main!C66 -> 2.09 | D15: =Main!D66 -> 2.07 | E15: =Main!E66 -> 1.7 | F15: =Main!F66 -> 1.94 | H15: Scandinavia | I15: =Main!I66 -> 1.44 | J15: =Main!J66 -> 1.24 | K15: =Main!K66 -> 1.09 | L15: =Main!L66 -> 1.21 | M15: =Main!M66 -> 1.25 | O15: Scandinavia | P15: =Main!P66 -> 0.739 | Q15: =Main!Q66 -> 1.65 | R15: =Main!R66 -> 0 | S15: =Main!S66 -> 0.592 | T15: =Main!T66 -> 1.16
A16: Iberian Peninsula | B16: =Main!B67 -> 1.53 | C16: =Main!C67 -> 0.388 | D16: =Main!D67 -> 1.17 | E16: =Main!E67 -> 0.47 | F16: =Main!F67 -> 0.87 | H16: Iberian Peninsula | I16: =Main!I67 -> 0.94 | J16: =Main!J67 -> 0 | K16: =Main!K67 -> 0.727 | L16: =Main!L67 -> 0.66 | M16: =Main!M67 -> 0.82 | O16: Iberian Peninsula | P16: =Main!P67 -> 0 | Q16: =Main!Q67 -> 0 | R16: =Main!R67 -> 0 | S16: =Main!S67 -> 0 | T16: =Main!T67 -> 0
M35: `
